Workbook

Sheet Monthly Tracker
A1: Year | B1: Month | C1: Planned EMI | D1: EMI Paid? (Y/N) | E1: Actual EMI | F1: Extra EMI Paid? (Y/N) | G1: Extra EMI Amount | H1: SIP Done? (Y/N) | I1: SIP Amount | J1: Prepayment
A2: 2026 | B2: Jan | C2: 29999 | I2: 5000
A3: 2026 | B3: Feb | C3: 29999 | I3: 5000
A4: 2026 | B4: Mar | C4: 29999 | I4: 5000
A5: 2026 | B5: Apr | C5: 29999 | I5: 5000
A6: 2026 | B6: May | C6: 29999 | I6: 5000
A7: 2026 | B7: Jun | C7: 29999 | I7: 5000
A8: 2026 | B8: Jul | C8: 29999 | I8: 5000
A9: 2026 | B9: Aug | C9: 29999 | I9: 5000
A10: 2026 | B10: Sep | C10: 29999 | I10: 5000
A11: 2026 | B11: Oct | C11: 29999 | I11: 5000
A12: 2026 | B12: Nov | C12: 29999 | I12: 5000
A13: 2026 | B13: Dec | C13: 29999 | I13: 5000
... A145: 2037 | B145: Dec | C145: 29999 | I145: 5000

Sheet Loan Tracker
A1: Month | B1: Opening Balance | C1: EMI Used | D1: Extra EMI | E1: Prepayment | F1: Interest | G1: Principal | H1: Closing Balance
B2: 3500000 | C2: =IF('Monthly Tracker'!D2="Y",'Monthly Tracker'!E2,0) | D2: =IF('Monthly Tracker'!F2="Y",'Monthly Tracker'!G2,0) | E2: ='Monthly Tracker'!J2 | F2: =B2*0.007 | G2: =C2+D2+E2-F2 | H2: =B2-G2
B3: =H2 | C3: =IF('Monthly Tracker'!D3="Y",'Monthly Tracker'!E3,0) | D3: =IF('Monthly Tracker'!F3="Y",'Monthly Tracker'!G3,0) | E3: ='Monthly Tracker'!J3 | F3: =B3*0.007 | G3: =C3+D3+E3-F3 | H3: =B3-G3
B4: =H3 | C4: =IF('Monthly Tracker'!D4="Y",'Monthly Tracker'!E4,0) | D4: =IF('Monthly Tracker'!F4="Y",'Monthly Tracker'!G4,0) | E4: ='Monthly Tracker'!J4 | F4: =B4*0.007 | G4: =C4+D4+E4-F4 | H4: =B4-G4
B5: =H4 | C5: =IF('Monthly Tracker'!D5="Y",'Monthly Tracker'!E5,0) | D5: =IF('Monthly Tracker'!F5="Y",'Monthly Tracker'!G5,0) | E5: ='Monthly Tracker'!J5 | F5: =B5*0.007 | G5: =C5+D5+E5-F5 | H5: =B5-G5
B6: =H5 | C6: =IF('Monthly Tracker'!D6="Y",'Monthly Tracker'!E6,0) | D6: =IF('Monthly Tracker'!F6="Y",'Monthly Tracker'!G6,0) | E6: ='Monthly Tracker'!J6 | F6: =B6*0.007 | G6: =C6+D6+E6-F6 | H6: =B6-G6
B7: =H6 | C7: =IF('Monthly Tracker'!D7="Y",'Monthly Tracker'!E7,0) | D7: =IF('Monthly Tracker'!F7="Y",'Monthly Tracker'!G7,0) | E7: ='Monthly Tracker'!J7 | F7: =B7*0.007 | G7: =C7+D7+E7-F7 | H7: =B7-G7
B8: =H7 | C8: =IF('Monthly Tracker'!D8="Y",'Monthly Tracker'!E8,0) | D8: =IF('Monthly Tracker'!F8="Y",'Monthly Tracker'!G8,0) | E8: ='Monthly Tracker'!J8 | F8: =B8*0.007 | G8: =C8+D8+E8-F8 | H8: =B8-G8
B9: =H8 | C9: =IF('Monthly Tracker'!D9="Y",'Monthly Tracker'!E9,0) | D9: =IF('Monthly Tracker'!F9="Y",'Monthly Tracker'!G9,0) | E9: ='Monthly Tracker'!J9 | F9: =B9*0.007 | G9: =C9+D9+E9-F9 | H9: =B9-G9
B10: =H9 | C10: =IF('Monthly Tracker'!D10="Y",'Monthly Tracker'!E10,0) | D10: =IF('Monthly Tracker'!F10="Y",'Monthly Tracker'!G10,0) | E10: ='Monthly Tracker'!J10 | F10: =B10*0.007 | G10: =C10+D10+E10-F10 | H10: =B10-G10
B11: =H10 | C11: =IF('Monthly Tracker'!D11="Y",'Monthly Tracker'!E11,0) | D11: =IF('Monthly Tracker'!F11="Y",'Monthly Tracker'!G11,0) | E11: ='Monthly Tracker'!J11 | F11: =B11*0.007 | G11: =C11+D11+E11-F11 | H11: =B11-G11
B12: =H11 | C12: =IF('Monthly Tracker'!D12="Y",'Monthly Tracker'!E12,0) | D12: =IF('Monthly Tracker'!F12="Y",'Monthly Tracker'!G12,0) | E12: ='Monthly Tracker'!J12 | F12: =B12*0.007 | G12: =C12+D12+E12-F12 | H12: =B12-G12
B13: =H12 | C13: =IF('Monthly Tracker'!D13="Y",'Monthly Tracker'!E13,0) | D13: =IF('Monthly Tracker'!F13="Y",'Monthly Tracker'!G13,0) | E13: ='Monthly Tracker'!J13 | F13: =B13*0.007 | G13: =C13+D13+E13-F13 | H13: =B13-G13
B14: =H13 | C14: =IF('Monthly Tracker'!D14="Y",'Monthly Tracker'!E14,0) | D14: =IF('Monthly Tracker'!F14="Y",'Monthly Tracker'!G14,0) | E14: ='Monthly Tracker'!J14 | F14: =B14*0.007 | G14: =C14+D14+E14-F14 | H14: =B14-G14
... B199: =H198 | C199: =IF('Monthly Tracker'!D199="Y",'Monthly Tracker'!E199,0) | D199: =IF('Monthly Tracker'!F199="Y",'Monthly Tracker'!G199,0) | E199: ='Monthly Tracker'!J199 | F199: =B199*0.007 | G199: =C199+D199+E199-F199 | H199: =B199-G199

Sheet SIP Growth
A1: Month | B1: SIP Used | C1: Total Invested | D1: Value
B2: =IF('Monthly Tracker'!H2="Y",'Monthly Tracker'!I2,0) | C2: =SUM(B2:B2) | D2: =B2*(1+0.01)^1
B3: =IF('Monthly Tracker'!H3="Y",'Monthly Tracker'!I3,0) | C3: =SUM(B2:B3) | D3: =B3*(1+0.01)^2
B4: =IF('Monthly Tracker'!H4="Y",'Monthly Tracker'!I4,0) | C4: =SUM(B2:B4) | D4: =B4*(1+0.01)^3
B5: =IF('Monthly Tracker'!H5="Y",'Monthly Tracker'!I5,0) | C5: =SUM(B2:B5) | D5: =B5*(1+0.01)^4
B6: =IF('Monthly Tracker'!H6="Y",'Monthly Tracker'!I6,0) | C6: =SUM(B2:B6) | D6: =B6*(1+0.01)^5
B7: =IF('Monthly Tracker'!H7="Y",'Monthly Tracker'!I7,0) | C7: =SUM(B2:B7) | D7: =B7*(1+0.01)^6
B8: =IF('Monthly Tracker'!H8="Y",'Monthly Tracker'!I8,0) | C8: =SUM(B2:B8) | D8: =B8*(1+0.01)^7
B9: =IF('Monthly Tracker'!H9="Y",'Monthly Tracker'!I9,0) | C9: =SUM(B2:B9) | D9: =B9*(1+0.01)^8
B10: =IF('Monthly Tracker'!H10="Y",'Monthly Tracker'!I10,0) | C10: =SUM(B2:B10) | D10: =B10*(1+0.01)^9
B11: =IF('Monthly Tracker'!H11="Y",'Monthly Tracker'!I11,0) | C11: =SUM(B2:B11) | D11: =B11*(1+0.01)^10
B12: =IF('Monthly Tracker'!H12="Y",'Monthly Tracker'!I12,0) | C12: =SUM(B2:B12) | D12: =B12*(1+0.01)^11
B13: =IF('Monthly Tracker'!H13="Y",'Monthly Tracker'!I13,0) | C13: =SUM(B2:B13) | D13: =B13*(1+0.01)^12
B14: =IF('Monthly Tracker'!H14="Y",'Monthly Tracker'!I14,0) | C14: =SUM(B2:B14) | D14: =B14*(1+0.01)^13
B15: =IF('Monthly Tracker'!H15="Y",'Monthly Tracker'!I15,0) | C15: =SUM(B2:B15) | D15: =B15*(1+0.01)^14
B16: =IF('Monthly Tracker'!H16="Y",'Monthly Tracker'!I16,0) | C16: =SUM(B2:B16) | D16: =B16*(1+0.01)^15
B17: =IF('Monthly Tracker'!H17="Y",'Monthly Tracker'!I17,0) | C17: =SUM(B2:B17) | D17: =B17*(1+0.01)^16
B18: =IF('Monthly Tracker'!H18="Y",'Monthly Tracker'!I18,0) | C18: =SUM(B2:B18) | D18: =B18*(1+0.01)^17
B19: =IF('Monthly Tracker'!H19="Y",'Monthly Tracker'!I19,0) | C19: =SUM(B2:B19) | D19: =B19*(1+0.01)^18
B20: =IF('Monthly Tracker'!H20="Y",'Monthly Tracker'!I20,0) | C20: =SUM(B2:B20) | D20: =B20*(1+0.01)^19
B21: =IF('Monthly Tracker'!H21="Y",'Monthly Tracker'!I21,0) | C21: =SUM(B2:B21) | D21: =B21*(1+0.01)^20
B22: =IF('Monthly Tracker'!H22="Y",'Monthly Tracker'!I22,0) | C22: =SUM(B2:B22) | D22: =B22*(1+0.01)^21
B23: =IF('Monthly Tracker'!H23="Y",'Monthly Tracker'!I23,0) | C23: =SUM(B2:B23) | D23: =B23*(1+0.01)^22
B24: =IF('Monthly Tracker'!H24="Y",'Monthly Tracker'!I24,0) | C24: =SUM(B2:B24) | D24: =B24*(1+0.01)^23
B25: =IF('Monthly Tracker'!H25="Y",'Monthly Tracker'!I25,0) | C25: =SUM(B2:B25) | D25: =B25*(1+0.01)^24
B26: =IF('Monthly Tracker'!H26="Y",'Monthly Tracker'!I26,0) | C26: =SUM(B2:B26) | D26: =B26*(1+0.01)^25
B27: =IF('Monthly Tracker'!H27="Y",'Monthly Tracker'!I27,0) | C27: =SUM(B2:B27) | D27: =B27*(1+0.01)^26
B28: =IF('Monthly Tracker'!H28="Y",'Monthly Tracker'!I28,0) | C28: =SUM(B2:B28) | D28: =B28*(1+0.01)^27
B29: =IF('Monthly Tracker'!H29="Y",'Monthly Tracker'!I29,0) | C29: =SUM(B2:B29) | D29: =B29*(1+0.01)^28
B30: =IF('Monthly Tracker'!H30="Y",'Monthly Tracker'!I30,0) | C30: =SUM(B2:B30) | D30: =B30*(1+0.01)^29
B31: =IF('Monthly Tracker'!H31="Y",'Monthly Tracker'!I31,0) | C31: =SUM(B2:B31) | D31: =B31*(1+0.01)^30
B32: =IF('Monthly Tracker'!H32="Y",'Monthly Tracker'!I32,0) | C32: =SUM(B2:B32) | D32: =B32*(1+0.01)^31
B33: =IF('Monthly Tracker'!H33="Y",'Monthly Tracker'!I33,0) | C33: =SUM(B2:B33) | D33: =B33*(1+0.01)^32
B34: =IF('Monthly Tracker'!H34="Y",'Monthly Tracker'!I34,0) | C34: =SUM(B2:B34) | D34: =B34*(1+0.01)^33
B35: =IF('Monthly Tracker'!H35="Y",'Monthly Tracker'!I35,0) | C35: =SUM(B2:B35) | D35: =B35*(1+0.01)^34
B36: =IF('Monthly Tracker'!H36="Y",'Monthly Tracker'!I36,0) | C36: =SUM(B2:B36) | D36: =B36*(1+0.01)^35
B37: =IF('Monthly Tracker'!H37="Y",'Monthly Tracker'!I37,0) | C37: =SUM(B2:B37) | D37: =B37*(1+0.01)^36
B38: =IF('Monthly Tracker'!H38="Y",'Monthly Tracker'!I38,0) | C38: =SUM(B2:B38) | D38: =B38*(1+0.01)^37
B39: =IF('Monthly Tracker'!H39="Y",'Monthly Tracker'!I39,0) | C39: =SUM(B2:B39) | D39: =B39*(1+0.01)^38
B40: =IF('Monthly Tracker'!H40="Y",'Monthly Tracker'!I40,0) | C40: =SUM(B2:B40) | D40: =B40*(1+0.01)^39
...
