Workbook

Sheet Monthly Tracker
A1: Year | B1: Month | C1: Planned EMI | D1: Actual EMI | E1: Extra EMI | F1: SIP | G1: Prepayment | H1: Status
A2: 2026 | B2: Jan | C2: 29999 | F2: 5000
A3: 2026 | B3: Feb | C3: 29999 | F3: 5000
A4: 2026 | B4: Mar | C4: 29999 | F4: 5000
A5: 2026 | B5: Apr | C5: 29999 | F5: 5000
A6: 2026 | B6: May | C6: 29999 | F6: 5000
A7: 2026 | B7: Jun | C7: 29999 | F7: 5000
A8: 2026 | B8: Jul | C8: 29999 | F8: 5000
A9: 2026 | B9: Aug | C9: 29999 | F9: 5000
A10: 2026 | B10: Sep | C10: 29999 | F10: 5000
A11: 2026 | B11: Oct | C11: 29999 | F11: 5000
A12: 2026 | B12: Nov | C12: 29999 | F12: 5000
A13: 2026 | B13: Dec | C13: 29999 | F13: 5000
... A145: 2037 | B145: Dec | C145: 29999 | F145: 5000

Sheet Loan Tracker
A1: Month | B1: Opening Balance | C1: EMI | D1: Prepayment | E1: Interest | F1: Principal | G1: Closing Balance
B2: 3500000 | C2: 29999 | D2: ='Monthly Tracker'!G2 | E2: =B2*0.007 | F2: =C2-E2+D2 | G2: =B2-F2
B3: =G2 | C3: 29999 | D3: ='Monthly Tracker'!G3 | E3: =B3*0.007 | F3: =C3-E3+D3 | G3: =B3-F3
B4: =G3 | C4: 29999 | D4: ='Monthly Tracker'!G4 | E4: =B4*0.007 | F4: =C4-E4+D4 | G4: =B4-F4
B5: =G4 | C5: 29999 | D5: ='Monthly Tracker'!G5 | E5: =B5*0.007 | F5: =C5-E5+D5 | G5: =B5-F5
B6: =G5 | C6: 29999 | D6: ='Monthly Tracker'!G6 | E6: =B6*0.007 | F6: =C6-E6+D6 | G6: =B6-F6
B7: =G6 | C7: 29999 | D7: ='Monthly Tracker'!G7 | E7: =B7*0.007 | F7: =C7-E7+D7 | G7: =B7-F7
B8: =G7 | C8: 29999 | D8: ='Monthly Tracker'!G8 | E8: =B8*0.007 | F8: =C8-E8+D8 | G8: =B8-F8
B9: =G8 | C9: 29999 | D9: ='Monthly Tracker'!G9 | E9: =B9*0.007 | F9: =C9-E9+D9 | G9: =B9-F9
B10: =G9 | C10: 29999 | D10: ='Monthly Tracker'!G10 | E10: =B10*0.007 | F10: =C10-E10+D10 | G10: =B10-F10
B11: =G10 | C11: 29999 | D11: ='Monthly Tracker'!G11 | E11: =B11*0.007 | F11: =C11-E11+D11 | G11: =B11-F11
B12: =G11 | C12: 29999 | D12: ='Monthly Tracker'!G12 | E12: =B12*0.007 | F12: =C12-E12+D12 | G12: =B12-F12
B13: =G12 | C13: 29999 | D13: ='Monthly Tracker'!G13 | E13: =B13*0.007 | F13: =C13-E13+D13 | G13: =B13-F13
B14: =G13 | C14: 29999 | D14: ='Monthly Tracker'!G14 | E14: =B14*0.007 | F14: =C14-E14+D14 | G14: =B14-F14
... B199: =G198 | C199: 29999 | D199: ='Monthly Tracker'!G199 | E199: =B199*0.007 | F199: =C199-E199+D199 | G199: =B199-F199

Sheet SIP Growth
A1: Month | B1: SIP | C1: Total Invested | D1: Value
A2: 1 | B2: ='Monthly Tracker'!F2 | C2: =SUM(B2:B2) | D2: =B2*(1+0.01)^1
A3: 2 | B3: ='Monthly Tracker'!F3 | C3: =SUM(B2:B3) | D3: =B3*(1+0.01)^2
A4: 3 | B4: ='Monthly Tracker'!F4 | C4: =SUM(B2:B4) | D4: =B4*(1+0.01)^3
A5: 4 | B5: ='Monthly Tracker'!F5 | C5: =SUM(B2:B5) | D5: =B5*(1+0.01)^4
A6: 5 | B6: ='Monthly Tracker'!F6 | C6: =SUM(B2:B6) | D6: =B6*(1+0.01)^5
A7: 6 | B7: ='Monthly Tracker'!F7 | C7: =SUM(B2:B7) | D7: =B7*(1+0.01)^6
A8: 7 | B8: ='Monthly Tracker'!F8 | C8: =SUM(B2:B8) | D8: =B8*(1+0.01)^7
A9: 8 | B9: ='Monthly Tracker'!F9 | C9: =SUM(B2:B9) | D9: =B9*(1+0.01)^8
A10: 9 | B10: ='Monthly Tracker'!F10 | C10: =SUM(B2:B10) | D10: =B10*(1+0.01)^9
A11: 10 | B11: ='Monthly Tracker'!F11 | C11: =SUM(B2:B11) | D11: =B11*(1+0.01)^10
A12: 11 | B12: ='Monthly Tracker'!F12 | C12: =SUM(B2:B12) | D12: =B12*(1+0.01)^11
A13: 12 | B13: ='Monthly Tracker'!F13 | C13: =SUM(B2:B13) | D13: =B13*(1+0.01)^12
A14: 13 | B14: ='Monthly Tracker'!F14 | C14: =SUM(B2:B14) | D14: =B14*(1+0.01)^13
A15: 14 | B15: ='Monthly Tracker'!F15 | C15: =SUM(B2:B15) | D15: =B15*(1+0.01)^14
A16: 15 | B16: ='Monthly Tracker'!F16 | C16: =SUM(B2:B16) | D16: =B16*(1+0.01)^15
A17: 16 | B17: ='Monthly Tracker'!F17 | C17: =SUM(B2:B17) | D17: =B17*(1+0.01)^16
A18: 17 | B18: ='Monthly Tracker'!F18 | C18: =SUM(B2:B18) | D18: =B18*(1+0.01)^17
A19: 18 | B19: ='Monthly Tracker'!F19 | C19: =SUM(B2:B19) | D19: =B19*(1+0.01)^18
A20: 19 | B20: ='Monthly Tracker'!F20 | C20: =SUM(B2:B20) | D20: =B20*(1+0.01)^19
A21: 20 | B21: ='Monthly Tracker'!F21 | C21: =SUM(B2:B21) | D21: =B21*(1+0.01)^20
A22: 21 | B22: ='Monthly Tracker'!F22 | C22: =SUM(B2:B22) | D22: =B22*(1+0.01)^21
A23: 22 | B23: ='Monthly Tracker'!F23 | C23: =SUM(B2:B23) | D23: =B23*(1+0.01)^22
A24: 23 | B24: ='Monthly Tracker'!F24 | C24: =SUM(B2:B24) | D24: =B24*(1+0.01)^23
A25: 24 | B25: ='Monthly Tracker'!F25 | C25: =SUM(B2:B25) | D25: =B25*(1+0.01)^24
A26: 25 | B26: ='Monthly Tracker'!F26 | C26: =SUM(B2:B26) | D26: =B26*(1+0.01)^25
A27: 26 | B27: ='Monthly Tracker'!F27 | C27: =SUM(B2:B27) | D27: =B27*(1+0.01)^26
A28: 27 | B28: ='Monthly Tracker'!F28 | C28: =SUM(B2:B28) | D28: =B28*(1+0.01)^27
A29: 28 | B29: ='Monthly Tracker'!F29 | C29: =SUM(B2:B29) | D29: =B29*(1+0.01)^28
A30: 29 | B30: ='Monthly Tracker'!F30 | C30: =SUM(B2:B30) | D30: =B30*(1+0.01)^29
A31: 30 | B31: ='Monthly Tracker'!F31 | C31: =SUM(B2:B31) | D31: =B31*(1+0.01)^30
A32: 31 | B32: ='Monthly Tracker'!F32 | C32: =SUM(B2:B32) | D32: =B32*(1+0.01)^31
A33: 32 | B33: ='Monthly Tracker'!F33 | C33: =SUM(B2:B33) | D33: =B33*(1+0.01)^32
A34: 33 | B34: ='Monthly Tracker'!F34 | C34: =SUM(B2:B34) | D34: =B34*(1+0.01)^33
A35: 34 | B35: ='Monthly Tracker'!F35 | C35: =SUM(B2:B35) | D35: =B35*(1+0.01)^34
A36: 35 | B36: ='Monthly Tracker'!F36 | C36: =SUM(B2:B36) | D36: =B36*(1+0.01)^35
A37: 36 | B37: ='Monthly Tracker'!F37 | C37: =SUM(B2:B37) | D37: =B37*(1+0.01)^36
A38: 37 | B38: ='Monthly Tracker'!F38 | C38: =SUM(B2:B38) | D38: =B38*(1+0.01)^37
A39: 38 | B39: ='Monthly Tracker'!F39 | C39: =SUM(B2:B39) | D39: =B39*(1+0.01)^38
A40: 39 | B40: ='Monthly Tracker'!F40 | C40: =SUM(B2:B40) | D40: =B40*(1+0.01)^39
...

Sheet Dashboard
A1: Financial Dashboard
A3: Total SIP Invested | B3: =SUM('SIP Growth'!C2:C200)
A4: SIP Value | B4: =MAX('SIP Growth'!D2:D200)
A5: Remaining Loan | B5: ='Loan Tracker'!G199
A6: Loan Free Status | B6: =IF(B5<=0,"Loan Closed 🎉","Active")

Sheet Alerts
A1: Month | B1: Alert
A2: Month 1 | B2: =IF('Monthly Tracker'!D2="","❌ EMI Missing","OK")
A3: Month 2 | B3: =IF('Monthly Tracker'!D3="","❌ EMI Missing","OK")
A4: Month 3 | B4: =IF('Monthly Tracker'!D4="","❌ EMI Missing","OK")
A5: Month 4 | B5: =IF('Monthly Tracker'!D5="","❌ EMI Missing","OK")
A6: Month 5 | B6: =IF('Monthly Tracker'!D6="","❌ EMI Missing","OK")
A7: Month 6 | B7: =IF('Monthly Tracker'!D7="","❌ EMI Missing","OK")
A8: Month 7 | B8: =IF('Monthly Tracker'!D8="","❌ EMI Missing","OK")
A9: Month 8 | B9: =IF('Monthly Tracker'!D9="","❌ EMI Missing","OK")
A10: Month 9 | B10: =IF('Monthly Tracker'!D10="","❌ EMI Missing","OK")
A11: Month 10 | B11: =IF('Monthly Tracker'!D11="","❌ EMI Missing","OK")
A12: Month 11 | B12: =IF('Monthly Tracker'!D12="","❌ EMI Missing","OK")
A13: Month 12 | B13: =IF('Monthly Tracker'!D13="","❌ EMI Missing","OK")
... A149: Month 148 | B149: =IF('Monthly Tracker'!D149="","❌ EMI Missing","OK")
